<?xml version="1.0" ?>
<robot name="panda" xmlns:xacro="http://www.ros.org/wiki/xacro">

	<link name="world">
	</link>

	<joint name="arm_joint0" type="fixed">
		<parent link="world"/>
		<child link="pris_link0"/>
		<origin rpy="0.0 0.0 0.0" xyz="0.0 0.0 0.0"/>
	</joint>

	<link name="pris_link0">
		<inertial>
		  <mass value="0.001"/>
		  <inertia ixx="0.1" iyy="0.1" izz="0.1" ixy="0.0" ixz="0.0" iyz="0.0"/>
		</inertial>  
	</link>

	<joint name="arm_joint1" type="prismatic">
		<parent link="pris_link0"/>
		<child link="pris_link1"/>
		<origin rpy="0.0 0.0 0.0" xyz="0.0 0.0 0.0"/>
		<axis xyz="1 0 0"/>
		<dynamics damping="10.0" friction="0.0"/>
		<limit lower="-1" upper="1" velocity="1e9" effort="1e9"/>
	</joint>


  	<link name="pris_link1">
		<inertial>
		  <mass value="0.001"/>
		  <inertia ixx="0.1" iyy="0.1" izz="0.1" ixy="0.0" ixz="0.0" iyz="0.0"/>
		</inertial>  
	</link>

	<joint name="arm_joint2" type="prismatic">
		<parent link="pris_link1"/>
		<child link="pris_link2"/>
		<origin rpy="0.0 0.0 0.0" xyz="0.0 0.0 0.0"/>
		<axis xyz="0 1 0"/>
		<dynamics damping="10.0" friction="0.0"/>
		<limit lower="-1" upper="1" velocity="1e9" effort="1e9"/>
	</joint>


  	<link name="pris_link2">
		<inertial>
		  <mass value="0.001"/>
		  <inertia ixx="0.1" iyy="0.1" izz="0.1" ixy="0.0" ixz="0.0" iyz="0.0"/>
		</inertial>  
	</link>


	<joint name="arm_joint3" type="prismatic">
		<parent link="pris_link2"/>
		<child link="rev_linkx"/>
		<origin rpy="0.0 0.0 0.0" xyz="0.0 0.0 0.0"/>
		<axis xyz="0 0 1"/>
		<dynamics damping="10.0" friction="0.0"/>
		<limit lower="-1" upper="1" velocity="1e9" effort="1e9"/>
	</joint>


  	<link name="rev_linkx">
		<inertial>
		  <mass value="0.001"/>
		  <inertia ixx="0.1" iyy="0.1" izz="0.1" ixy="0.0" ixz="0.0" iyz="0.0"/>
		  <origin rpy="0 0 0" xyz="0.0 0.0 0.0"/>
		</inertial>  
	</link>


	<joint name="rev_jointz" type="revolute">
		<axis xyz="0 0 1"/>
		<dynamics damping="10.0" friction="0.0"/>
		<limit effort="1e9" lower="-3.14" upper="3.14" velocity="1e9"/>
		<origin rpy="0 0 0" xyz="0.0 0.0 -0.0"/>
		<parent link="rev_linkx"/>
		<child link="rev_linky"/>
	</joint>

  	<link name="rev_linky">
		<inertial>
		  <mass value="0.001"/>
		  <inertia ixx="0.1" iyy="0.1" izz="0.1" ixy="0.0" ixz="0.0" iyz="0.0"/>
		  <origin rpy="0 0 0" xyz="0.0 0.0 0.0"/>

		</inertial>  
	</link>


	<joint name="rev_jointy" type="revolute">
		<axis xyz="0 1 0"/>
		<dynamics damping="10.0" friction="0.0"/>
		<limit effort="1e9" lower="-3.14" upper="3.14" velocity="1e9"/>
		<origin rpy="0 0 0" xyz="0.0 0.0 -0.0"/>
		<parent link="rev_linky"/>
		<child link="rev_linkz"/>
	</joint>

  	<link name="rev_linkz">
		<inertial>
		  <mass value="0.001"/>
		  <inertia ixx="0.1" iyy="0.1" izz="0.1" ixy="0.0" ixz="0.0" iyz="0.0"/>
		</inertial>  
	</link>


	<joint name="rev_jointx" type="revolute">
		<axis xyz="1 0 0"/>
		<dynamics damping="10.0" friction="0.0"/>
		<limit effort="1e9.0" lower="-3.14" upper="3.14" velocity="1e9"/>
		<origin rpy="0 0 0" xyz="0.0 0.0 -0.0"/>
		<parent link="rev_linkz"/>
		<child link="rev_link_end"/>
	</joint>


  	<link name="rev_link_end">
		<inertial>
		  <mass value="0.001"/>
		  <inertia ixx="0.1" iyy="0.1" izz="0.1" ixy="0.0" ixz="0.0" iyz="0.0"/>
		</inertial>  
	</link>

<joint name="panda_hand_joint" type="fixed">
    <!--
    <parent link="panda_link8"/>
    -->
    <parent link="rev_link_end"/>
    <child link="panda_hand"/>
    <origin rpy="0 0 0.0" xyz="0 0 0.0"/>
    <!--
    <origin rpy="0 0 -0.785398163397" xyz="0 0 0"/>
    -->
  </joint>
  <link name="panda_hand">
    <visual>
      <geometry>
        <mesh filename="package://franka_description/meshes/visual/hand.dae"/>
      </geometry>
    </visual>
    <collision>
      <geometry>
        <mesh filename="package://franka_description/meshes/collision/hand.obj"/>
      </geometry>
    </collision>
  </link>
  <link name="panda_leftfinger">
    <visual>
      <geometry>
        <mesh filename="package://franka_description/meshes/visual/finger.dae"/>
      </geometry>
    </visual>
    <collision>
      <geometry>
        <mesh filename="package://franka_description/meshes/collision/finger.obj"/>
      </geometry>
    </collision>
  </link>
  <link name="panda_rightfinger">
    <visual>
      <origin rpy="0 0 3.14159265359" xyz="0 0 0"/>
      <geometry>
        <mesh filename="package://franka_description/meshes/visual/finger.dae"/>
      </geometry>
    </visual>
    <collision>
      <origin rpy="0 0 3.14159265359" xyz="0 0 0"/>
      <geometry>
        <mesh filename="package://franka_description/meshes/collision/finger.obj"/>
      </geometry>
    </collision>
  </link>
  <joint name="panda_finger_joint1" type="prismatic">
    <parent link="panda_hand"/>
    <child link="panda_leftfinger"/>
    <origin rpy="0 0 0" xyz="0 0 0.0584"/>
    <axis xyz="0 1 0"/>
    <dynamics damping="10.0"/>
    <limit effort="20" lower="0.0" upper="0.04" velocity="0.2"/>
  </joint>
  <joint name="panda_finger_joint2" type="prismatic">
    <parent link="panda_hand"/>
    <child link="panda_rightfinger"/>
    <origin rpy="0 0 0" xyz="0 0 0.0584"/>
    <axis xyz="0 -1 0"/>
    <dynamics damping="10.0"/>
    <limit effort="20" lower="0.0" upper="0.04" velocity="0.2"/>
    <mimic joint="panda_finger_joint1"/>
  </joint>
</robot>
	
	

	

    


</robot>
